(dp1
S'output'
p2
S'<class \'gluon.contrib.pymysql.err.ProgrammingError\'> (1146, u"Table \'ayd2.Catedratico_archive\' doesn\'t exist")'
p3
sS'layer'
p4
S'/home/erick/web2py/applications/Fase_I_Suy/models/db_wizard.py'
p5
sS'code'
p6
S"db.define_table('Catedratico',\n                Field('Nombre', type='string', label=T('Nombre'),notnull=True),\n                Field('Dpi', type='string', label=T('DPI')),\n                Field('Telefono', type='integer', label=T('TELEFONO')),\n                Field('Especializacion', type='integer', label=T('ESPECIALIZACION')),\n                migrate=False)\n\ndb.define_table('Catedratico_archive',db.Catedratico,Field('current_record','reference Catedratico',readable=False,writable=False))\n"
p7
sS'snapshot'
p8
(dp9
sS'traceback'
p10
S'Traceback (most recent call last):\n  File "/home/erick/web2py/gluon/restricted.py", line 227, in restricted\n    exec ccode in environment\n  File "/home/erick/web2py/applications/Fase_I_Suy/models/db_wizard.py", line 8, in <module>\n    db.define_table(\'Catedratico_archive\',db.Catedratico,Field(\'current_record\',\'reference Catedratico\',readable=False,writable=False))\n  File "/home/erick/web2py/gluon/packages/dal/pydal/base.py", line 834, in define_table\n    table = self.lazy_define_table(tablename,*fields,**args)\n  File "/home/erick/web2py/gluon/packages/dal/pydal/base.py", line 873, in lazy_define_table\n    polymodel=polymodel)\n  File "/home/erick/web2py/gluon/packages/dal/pydal/adapters/base.py", line 510, in create_table\n    fake_migrate=fake_migrate\n  File "/home/erick/web2py/gluon/packages/dal/pydal/adapters/base.py", line 623, in migrate_table\n    self.execute(sub_query)\n  File "/home/erick/web2py/gluon/packages/dal/pydal/adapters/base.py", line 1385, in execute\n    return self.log_execute(*a, **b)\n  File "/home/erick/web2py/gluon/packages/dal/pydal/adapters/base.py", line 1379, in log_execute\n    ret = self.get_cursor().execute(command, *a[1:], **b)\n  File "/home/erick/web2py/gluon/contrib/pymysql/cursors.py", line 117, in execute\n    self.errorhandler(self, exc, value)\n  File "/home/erick/web2py/gluon/contrib/pymysql/connections.py", line 202, in defaulterrorhandler\n    raise errorclass, errorvalue\nProgrammingError: (1146, u"Table \'ayd2.Catedratico_archive\' doesn\'t exist")\n'
p11
s.