(dp1
S'output'
p2
S'<class \'gluon.contrib.pymysql.err.ProgrammingError\'> (1146, u"Table \'ayd2.Catedratico_archive\' doesn\'t exist")'
p3
sS'layer'
p4
S'/home/erick/web2py/applications/Fase_I_Suy/controllers/default.py'
p5
sS'code'
p6
S"# -*- coding: utf-8 -*-\n### required - do no delete\ndef user(): return dict(form=auth())\ndef download(): return response.download(request,db)\ndef call(): return service()\n### end requires\ndef index():\n    return dict()\n\n@auth.requires_login()\ndef catedratico():\n   form = SQLFORM(db.Catedratico)\n   grid = SQLFORM.smartgrid(db.Catedratico,onupdate=auth.archive,formname='web2py_grid')\n   if form.process(formname='registro').accepted:\n       response.flash = 'Se ha registrado una nueva especializacion'\n   elif form.errors:\n       response.flash = 'El formulario tiene errores'\n   return dict(form=form, grid=grid)\n\n\n\ndef error():\n    return dict()\n\nresponse._vars=response._caller(catedratico)\n"
p7
sS'snapshot'
p8
(dp9
sS'traceback'
p10
S'Traceback (most recent call last):\n  File "/home/erick/web2py/gluon/restricted.py", line 227, in restricted\n    exec ccode in environment\n  File "/home/erick/web2py/applications/Fase_I_Suy/controllers/default.py", line 25, in <module>\n  File "/home/erick/web2py/gluon/globals.py", line 412, in <lambda>\n    self._caller = lambda f: f()\n  File "/home/erick/web2py/gluon/tools.py", line 4236, in f\n    return action(*a, **b)\n  File "/home/erick/web2py/applications/Fase_I_Suy/controllers/default.py", line 13, in catedratico\n    grid = SQLFORM.smartgrid(db.Catedratico,onupdate=auth.archive,formname=\'web2py_grid\')\n  File "/home/erick/web2py/gluon/sqlhtml.py", line 3056, in smartgrid\n    user_signature=user_signature, **kwargs)\n  File "/home/erick/web2py/gluon/sqlhtml.py", line 2319, in grid\n    next=referrer)\n  File "/home/erick/web2py/gluon/html.py", line 2304, in process\n    self.validate(**kwargs)\n  File "/home/erick/web2py/gluon/html.py", line 2248, in validate\n    onsuccess(self)\n  File "/home/erick/web2py/gluon/tools.py", line 4640, in archive\n    *[field.clone(unique=False) for field in table])\n  File "/home/erick/web2py/gluon/packages/dal/pydal/base.py", line 834, in define_table\n    table = self.lazy_define_table(tablename,*fields,**args)\n  File "/home/erick/web2py/gluon/packages/dal/pydal/base.py", line 873, in lazy_define_table\n    polymodel=polymodel)\n  File "/home/erick/web2py/gluon/packages/dal/pydal/adapters/base.py", line 510, in create_table\n    fake_migrate=fake_migrate\n  File "/home/erick/web2py/gluon/packages/dal/pydal/adapters/base.py", line 623, in migrate_table\n    self.execute(sub_query)\n  File "/home/erick/web2py/gluon/packages/dal/pydal/adapters/base.py", line 1385, in execute\n    return self.log_execute(*a, **b)\n  File "/home/erick/web2py/gluon/packages/dal/pydal/adapters/base.py", line 1379, in log_execute\n    ret = self.get_cursor().execute(command, *a[1:], **b)\n  File "/home/erick/web2py/gluon/contrib/pymysql/cursors.py", line 117, in execute\n    self.errorhandler(self, exc, value)\n  File "/home/erick/web2py/gluon/contrib/pymysql/connections.py", line 202, in defaulterrorhandler\n    raise errorclass, errorvalue\nProgrammingError: (1146, u"Table \'ayd2.Catedratico_archive\' doesn\'t exist")\n'
p11
s.